Traceback (most recent call last):
  File "/Users/fsultan/opt/anaconda3/lib/python3.9/site-packages/jupyter_cache/executors/utils.py", line 58, in single_nb_execution
    executenb(
  File "/Users/fsultan/opt/anaconda3/lib/python3.9/site-packages/nbclient/client.py", line 1204, in execute
    return NotebookClient(nb=nb, resources=resources, km=km, **kwargs).execute()
  File "/Users/fsultan/opt/anaconda3/lib/python3.9/site-packages/nbclient/util.py", line 84, in wrapped
    return just_run(coro(*args, **kwargs))
  File "/Users/fsultan/opt/anaconda3/lib/python3.9/site-packages/nbclient/util.py", line 62, in just_run
    return loop.run_until_complete(coro)
  File "/Users/fsultan/opt/anaconda3/lib/python3.9/asyncio/base_events.py", line 647, in run_until_complete
    return future.result()
  File "/Users/fsultan/opt/anaconda3/lib/python3.9/site-packages/nbclient/client.py", line 663, in async_execute
    await self.async_execute_cell(
  File "/Users/fsultan/opt/anaconda3/lib/python3.9/site-packages/nbclient/client.py", line 965, in async_execute_cell
    await self._check_raise_for_error(cell, cell_index, exec_reply)
  File "/Users/fsultan/opt/anaconda3/lib/python3.9/site-packages/nbclient/client.py", line 862, in _check_raise_for_error
    raise CellExecutionError.from_cell_and_msg(cell, exec_reply_content)
nbclient.exceptions.CellExecutionError: An error occurred while executing the following cell:
------------------
# Test your code here

jane = Student(123, "Jane Doe", 20, "john.doe@furman.edu")
john = Student(124, "John Doe", 21, "john.doe@furman.edu")
bob  = Student(125, "Bob Doe",  22,  "bob@furman.edu")
 
# for course in Course.get_all_courses():
#     jane.enroll_course(course)
#     john.enroll_course(course)
#     bob.enroll_course(course)

for course in Course.get_all_courses():
    jane.add_grade(course, 100)
    john.add_grade(course, 90)
    bob.add_grade(course, 80)

assert jane.get_avg_grade() == 100, "Test case 1 failed"
assert john.get_avg_grade() == 90,  "Test case 2 failed"
assert bob.get_avg_grade()  == 80,  "Test case 3 failed"

assert john.reason_for_absence() == "Not feeling well", "Test case 4 failed"
assert bob.reason_for_absence()  == "Not feeling well", "Test case 5 failed"
assert jane.reason_for_absence() == "Not feeling well", "Test case 6 failed"

for course in Course.get_all_courses():
    assert course.enrolled_students == [jane, john, bob], "Test case 7 failed"

alice = Student(126, "Alice Doe", 23, "alice@furman.edu")

try: 
    alice.add_grade(csc105, 100)
    assert "Test case 8 failed"
except Exception as e:
    pass

print("All test cases passed :)")

------------------

[0;31m---------------------------------------------------------------------------[0m
[0;31mAssertionError[0m                            Traceback (most recent call last)
Input [0;32mIn [8][0m, in [0;36m<cell line: 25>[0;34m()[0m
[1;32m     23[0m [38;5;28;01massert[39;00m jane[38;5;241m.[39mreason_for_absence() [38;5;241m==[39m [38;5;124m"[39m[38;5;124mNot feeling well[39m[38;5;124m"[39m, [38;5;124m"[39m[38;5;124mTest case 6 failed[39m[38;5;124m"[39m
[1;32m     25[0m [38;5;28;01mfor[39;00m course [38;5;129;01min[39;00m Course[38;5;241m.[39mget_all_courses():
[0;32m---> 26[0m     [38;5;28;01massert[39;00m course[38;5;241m.[39menrolled_students [38;5;241m==[39m [jane, john, bob], [38;5;124m"[39m[38;5;124mTest case 7 failed[39m[38;5;124m"[39m
[1;32m     28[0m alice [38;5;241m=[39m Student([38;5;241m126[39m, [38;5;124m"[39m[38;5;124mAlice Doe[39m[38;5;124m"[39m, [38;5;241m23[39m, [38;5;124m"[39m[38;5;124malice@furman.edu[39m[38;5;124m"[39m)
[1;32m     30[0m [38;5;28;01mtry[39;00m: 

[0;31mAssertionError[0m: Test case 7 failed
AssertionError: Test case 7 failed

