Traceback (most recent call last):
  File "/Users/fsultan/opt/anaconda3/lib/python3.9/site-packages/jupyter_cache/executors/utils.py", line 58, in single_nb_execution
    executenb(
  File "/Users/fsultan/opt/anaconda3/lib/python3.9/site-packages/nbclient/client.py", line 1204, in execute
    return NotebookClient(nb=nb, resources=resources, km=km, **kwargs).execute()
  File "/Users/fsultan/opt/anaconda3/lib/python3.9/site-packages/nbclient/util.py", line 84, in wrapped
    return just_run(coro(*args, **kwargs))
  File "/Users/fsultan/opt/anaconda3/lib/python3.9/site-packages/nbclient/util.py", line 62, in just_run
    return loop.run_until_complete(coro)
  File "/Users/fsultan/opt/anaconda3/lib/python3.9/asyncio/base_events.py", line 647, in run_until_complete
    return future.result()
  File "/Users/fsultan/opt/anaconda3/lib/python3.9/site-packages/nbclient/client.py", line 663, in async_execute
    await self.async_execute_cell(
  File "/Users/fsultan/opt/anaconda3/lib/python3.9/site-packages/nbclient/client.py", line 965, in async_execute_cell
    await self._check_raise_for_error(cell, cell_index, exec_reply)
  File "/Users/fsultan/opt/anaconda3/lib/python3.9/site-packages/nbclient/client.py", line 862, in _check_raise_for_error
    raise CellExecutionError.from_cell_and_msg(cell, exec_reply_content)
nbclient.exceptions.CellExecutionError: An error occurred while executing the following cell:
------------------
txt = ""

for i in range(10):
    print("Number of characters: ", len(txt), "\t Memory (in bytes):", sys.getsizeof(txt))
    txt += "0"

------------------

[0;31m---------------------------------------------------------------------------[0m
[0;31mNameError[0m                                 Traceback (most recent call last)
Input [0;32mIn [1][0m, in [0;36m<cell line: 3>[0;34m()[0m
[1;32m      1[0m txt [38;5;241m=[39m [38;5;124m"[39m[38;5;124m"[39m
[1;32m      3[0m [38;5;28;01mfor[39;00m i [38;5;129;01min[39;00m [38;5;28mrange[39m([38;5;241m10[39m):
[0;32m----> 4[0m     [38;5;28mprint[39m([38;5;124m"[39m[38;5;124mNumber of characters: [39m[38;5;124m"[39m, [38;5;28mlen[39m(txt), [38;5;124m"[39m[38;5;130;01m\t[39;00m[38;5;124m Memory (in bytes):[39m[38;5;124m"[39m, [43msys[49m[38;5;241m.[39mgetsizeof(txt))
[1;32m      5[0m     txt [38;5;241m+[39m[38;5;241m=[39m [38;5;124m"[39m[38;5;124m0[39m[38;5;124m"[39m

[0;31mNameError[0m: name 'sys' is not defined
NameError: name 'sys' is not defined

