Traceback (most recent call last):
  File "/Users/fsultan/opt/anaconda3/lib/python3.9/site-packages/jupyter_cache/executors/utils.py", line 58, in single_nb_execution
    executenb(
  File "/Users/fsultan/opt/anaconda3/lib/python3.9/site-packages/nbclient/client.py", line 1204, in execute
    return NotebookClient(nb=nb, resources=resources, km=km, **kwargs).execute()
  File "/Users/fsultan/opt/anaconda3/lib/python3.9/site-packages/nbclient/util.py", line 84, in wrapped
    return just_run(coro(*args, **kwargs))
  File "/Users/fsultan/opt/anaconda3/lib/python3.9/site-packages/nbclient/util.py", line 62, in just_run
    return loop.run_until_complete(coro)
  File "/Users/fsultan/opt/anaconda3/lib/python3.9/asyncio/base_events.py", line 647, in run_until_complete
    return future.result()
  File "/Users/fsultan/opt/anaconda3/lib/python3.9/site-packages/nbclient/client.py", line 663, in async_execute
    await self.async_execute_cell(
  File "/Users/fsultan/opt/anaconda3/lib/python3.9/site-packages/nbclient/client.py", line 965, in async_execute_cell
    await self._check_raise_for_error(cell, cell_index, exec_reply)
  File "/Users/fsultan/opt/anaconda3/lib/python3.9/site-packages/nbclient/client.py", line 862, in _check_raise_for_error
    raise CellExecutionError.from_cell_and_msg(cell, exec_reply_content)
nbclient.exceptions.CellExecutionError: An error occurred while executing the following cell:
------------------
current_time = Time()
current_time.hours = 9
current_time.minutes = 14
current_time.seconds = 30
print_time(current_time)
------------------

[0;31m---------------------------------------------------------------------------[0m
[0;31mNameError[0m                                 Traceback (most recent call last)
Input [0;32mIn [1][0m, in [0;36m<cell line: 1>[0;34m()[0m
[0;32m----> 1[0m current_time [38;5;241m=[39m [43mTime[49m()
[1;32m      2[0m current_time[38;5;241m.[39mhours [38;5;241m=[39m [38;5;241m9[39m
[1;32m      3[0m current_time[38;5;241m.[39mminutes [38;5;241m=[39m [38;5;241m14[39m

[0;31mNameError[0m: name 'Time' is not defined
NameError: name 'Time' is not defined

